<?xml version="1.0" encoding="utf-8"?>
<!-- This URDF was automatically created by SolidWorks to URDF Exporter! Originally created by Stephen Brawner (brawner@gmail.com) 
     Commit Version: 1.6.0-4-g7f85cfe  Build Version: 1.6.7995.38578
     For more information, please see http://wiki.ros.org/sw_urdf_exporter -->
<robot
  name="xhand_left">

  <link name="base_link"/>
  <joint name="base_joint" type="fixed">
    <parent link="base_link"/>
    <child link="left_hand_link"/>
    <origin xyz="0 0 0" rpy="3.14 0 -1.57"/>
  </joint>
  <link
    name="left_hand_link">
    <inertial>
      <origin
        xyz="-0.00332669287155695 -0.0101781679017775 -0.0570610488181998"
        rpy="0 0 0" />
      <mass
        value="0.53910397" />
      <inertia
        ixx="0.00046461"
        ixy="-0.0000027"
        ixz="-0.00005111"
        iyy="0.00064437"
        iyz="-0.00000218"
        izz="0.00027759" />
    </inertial>
    <visual>
      <origin
        xyz="0 0 0"
        rpy="0 0 0" />
      <geometry>
        <mesh
          filename="meshes/left_hand_link.STL" />
      </geometry>
      <material
        name="RAL_9005_Jet_Black">
        <color
          rgba="0.055 0.055 0.063 1" />
      </material>
    </visual>
    <collision>
      <origin
        xyz="0 0 0"
        rpy="0 0 0" />
      <geometry>
        <mesh
          filename="meshes/left_hand_link.STL" />
      </geometry>
    </collision>
  </link>
  <link
    name="left_hand_ee_link">
    <inertial>
      <origin
        xyz="-9.14235300816632E-20 6.87814821208628E-18 0"
        rpy="0 0 0" />
      <mass
        value="0.00000565" />
      <inertia
        ixx="0.00000000001"
        ixy="0.00000000001"
        ixz="0.00000000001"
        iyy="0.00000000001"
        iyz="0.00000000001"
        izz="0.00000000001" />
    </inertial>
    <visual>
      <origin
        xyz="0 0 0"
        rpy="0 0 0" />
      <geometry>
        <mesh
          filename="meshes/left_hand_ee_link.STL" />
      </geometry>
      <material
        name="RAL_9005_Jet_Black">
        <color
          rgba="0.055 0.055 0.063 1" />
      </material>
    </visual>
    <collision>
      <origin
        xyz="0 0 0"
        rpy="0 0 0" />
      <geometry>
        <mesh
          filename="meshes/left_hand_ee_link.STL" />
      </geometry>
    </collision>
  </link>
  <joint
    name="left_hand_ee_joint"
    type="fixed">
    <origin
      xyz="0 0 -0.065"
      rpy="0 0 0" />
    <parent
      link="left_hand_link" />
    <child
      link="left_hand_ee_link" />
    <axis
      xyz="0 0 0" />
  </joint>
  <link
    name="left_hand_back_link">
    <inertial>
      <origin
        xyz="-0.00206614328070064 0.0140092020913419 0.000644119291874204"
        rpy="0 0 0" />
      <mass
        value="0.00000020" />
      <inertia
        ixx="0.00000000001"
        ixy="0.00000000001"
        ixz="0.00000000001"
        iyy="0.00000000001"
        iyz="0.00000000001"
        izz="0.00000000001" />
    </inertial>
    <visual>
      <origin
        xyz="0 0 0"
        rpy="0 0 0" />
      <geometry>
        <mesh
          filename="meshes/left_hand_back_link.STL" />
      </geometry>
      <material
        name="RAL_9003_Signal_White">
        <color
          rgba="0.941 0.941 0.941 1" />
      </material>
    </visual>
    <collision>
      <origin
        xyz="0 0 0"
        rpy="0 0 0" />
      <geometry>
        <mesh
          filename="meshes/left_hand_back_link.STL" />
      </geometry>
    </collision>
  </link>
  <joint
    name="left_hand_back_joint"
    type="fixed">
    <origin
      xyz="0 0 -0.065"
      rpy="0 0 0" />
    <parent
      link="left_hand_link" />
    <child
      link="left_hand_back_link" />
    <axis
      xyz="0 0 0" />
    <dynamics
      damping="0"
      friction="0" />
  </joint>
  <link
    name="left_hand_thumb_bend_link">
    <inertial>
      <origin
        xyz="0.0144315029292586 0.00116653625408803 -6.50665966587562E-05"
        rpy="0 0 0" />
      <mass
        value="0.0118729" />
      <inertia
        ixx="0.00000062"
        ixy="0.00000004"
        ixz="-0.00000008"
        iyy="0.0000016"
        iyz="0.00000000001"
        izz="0.00000162" />
    </inertial>
    <visual>
      <origin
        xyz="0 0 0"
        rpy="0 0 0" />
      <geometry>
        <mesh
          filename="meshes/left_hand_thumb_bend_link.STL" />
      </geometry>
      <material
        name="RAL_9005_Jet_Black">
        <color
          rgba="0.055 0.055 0.063 1" />
      </material>
    </visual>
    <collision>
      <origin
        xyz="0 0 0"
        rpy="0 0 0" />
      <geometry>
        <mesh
          filename="meshes/left_hand_thumb_bend_link.STL" />
      </geometry>
    </collision>
  </link>
  <joint
    name="left_hand_thumb_bend_joint"
    type="revolute">
    <origin
      xyz="0.0228 -0.0095 -0.0305"
      rpy="0 0 0" />
    <parent
      link="left_hand_link" />
    <child
      link="left_hand_thumb_bend_link" />
    <axis
      xyz="0 0 -1" />
    <limit
      lower="0"
      upper="1.832"
      effort="1.1"
      velocity="8.63" />
    <dynamics
      damping="0"
      friction="0" />
  </joint>
  <link
    name="left_hand_thumb_rota_link1">
    <inertial>
      <origin
        xyz="0.028699400584835 0.000353013004294657 -0.0013521057380018"
        rpy="0 0 0" />
      <mass
        value="0.13268494" />
      <inertia
        ixx="0.00001702"
        ixy="0.00000762"
        ixz="-0.00000176"
        iyy="0.00003592"
        iyz="0.00000197"
        izz="0.00004285" />
    </inertial>
    <visual>
      <origin
        xyz="0 0 0"
        rpy="0 0 0" />
      <geometry>
        <mesh
          filename="meshes/left_hand_thumb_rota_link1.STL" />
      </geometry>
      <material
        name="RAL_9005_Jet_Black">
        <color
          rgba="0.055 0.055 0.063 1" />
      </material>
    </visual>
    <collision>
      <origin
        xyz="0 0 0"
        rpy="0 0 0" />
      <geometry>
        <mesh
          filename="meshes/left_hand_thumb_rota_link1.STL" />
      </geometry>
    </collision>
  </link>
  <joint
    name="left_hand_thumb_rota_joint1"
    type="revolute">
    <origin
      xyz="0.028599 -0.0083177 0.00178"
      rpy="-0.2618 0 -0.0407" />
    <parent
      link="left_hand_thumb_bend_link" />
    <child
      link="left_hand_thumb_rota_link1" />
    <axis
      xyz="0 1 0" />
    <limit
      lower="-0.698"
      upper="1.745"
      effort="1.1"
      velocity="8.63" />
    <dynamics
      damping="0"
      friction="0" />
  </joint>
  <link
    name="left_hand_thumb_rotaback_link1">
    <inertial>
      <origin
        xyz="-0.0296284435379629 -0.00145635345487384 0.00757347054072984"
        rpy="0 0 0" />
      <mass
        value="0.00000006" />
      <inertia
        ixx="0.00000000001"
        ixy="0.00000000001"
        ixz="0.00000000001"
        iyy="0.00000000001"
        iyz="0.00000000001"
        izz="0.00000000001" />
    </inertial>
    <visual>
      <origin
        xyz="0 0 0"
        rpy="0 0 0" />
      <geometry>
        <mesh
          filename="meshes/left_hand_thumb_rotaback_link1.STL" />
      </geometry>
      <material
        name="RAL_9003_Signal_White">
        <color
          rgba="0.941 0.941 0.941 1" />
      </material>
    </visual>
    <collision>
      <origin
        xyz="0 0 0"
        rpy="0 0 0" />
      <geometry>
        <mesh
          filename="meshes/left_hand_thumb_rotaback_link1.STL" />
      </geometry>
    </collision>
  </link>
  <joint
    name="left_hand_thumb_rotaback_joint1"
    type="fixed">
    <origin
      xyz="0.0553000000000004 0 0"
      rpy="0 0 0" />
    <parent
      link="left_hand_thumb_rota_link1" />
    <child
      link="left_hand_thumb_rotaback_link1" />
    <axis
      xyz="0 0 0" />
    <dynamics
      damping="0"
      friction="0" />
  </joint>
  <link
    name="left_hand_thumb_rota_link2">
    <inertial>
      <origin
        xyz="0.0228414266462457 0.000460794125797265 -0.000578251645405752"
        rpy="0 0 0" />
      <mass
        value="0.03536566" />
      <inertia
        ixx="0.00000353"
        ixy="-0.0000001"
        ixz="0.00000021"
        iyy="0.00000785"
        iyz="0.00000038"
        izz="0.00000898" />
    </inertial>
    <visual>
      <origin
        xyz="0 0 0"
        rpy="0 0 0" />
      <geometry>
        <mesh
          filename="meshes/left_hand_thumb_rota_link2.STL" />
      </geometry>
      <material
        name="RAL_9005_Jet_Black">
        <color
          rgba="0.055 0.055 0.063 1" />
      </material>
    </visual>
    <collision>
      <origin
        xyz="0 0 0"
        rpy="0 0 0" />
      <geometry>
        <mesh
          filename="meshes/left_hand_thumb_rota_link2.STL" />
      </geometry>
    </collision>
  </link>
  <joint
    name="left_hand_thumb_rota_joint2"
    type="revolute">
    <origin
      xyz="0.0553 0 0"
      rpy="0 0 0" />
    <parent
      link="left_hand_thumb_rota_link1" />
    <child
      link="left_hand_thumb_rota_link2" />
    <axis
      xyz="0 1 0" />
    <limit
      lower="0"
      upper="1.745"
      effort="0.4"
      velocity="14.38" />
    <dynamics
      damping="0"
      friction="0" />
  </joint>
  <link
    name="left_hand_thumb_rotaback_link2">
    <inertial>
      <origin
        xyz="-0.0256682291910944 0.000513274886833534 0.00926148645051527"
        rpy="0 0 0" />
      <mass
        value="0.00000004" />
      <inertia
        ixx="0.00000000001"
        ixy="0.00000000001"
        ixz="0.00000000001"
        iyy="0.00000000001"
        iyz="0.00000000001"
        izz="0.00000000001" />
    </inertial>
    <visual>
      <origin
        xyz="0 0 0"
        rpy="0 0 0" />
      <geometry>
        <mesh
          filename="meshes/left_hand_thumb_rotaback_link2.STL" />
      </geometry>
      <material
        name="RAL_9003_Signal_White">
        <color
          rgba="0.941 0.941 0.941 1" />
      </material>
    </visual>
    <collision>
      <origin
        xyz="0 0 0"
        rpy="0 0 0" />
      <geometry>
        <mesh
          filename="meshes/left_hand_thumb_rotaback_link2.STL" />
      </geometry>
    </collision>
  </link>
  <joint
    name="left_hand_thumb_rotaback_joint2"
    type="fixed">
    <origin
      xyz="0.0499881470979494 0 0"
      rpy="0 0 0" />
    <parent
      link="left_hand_thumb_rota_link2" />
    <child
      link="left_hand_thumb_rotaback_link2" />
    <axis
      xyz="0 0 0" />
    <dynamics
      damping="0"
      friction="0" />
  </joint>
  <link
    name="left_hand_thumb_rota_tip">
    <inertial>
      <origin
        xyz="-8.32667268468867E-17 1.04083408558608E-17 2.28983498828939E-16"
        rpy="0 0 0" />
      <mass
        value="0.00000565" />
      <inertia
        ixx="0.00000000001"
        ixy="0.00000000001"
        ixz="0.00000000001"
        iyy="0.00000000001"
        iyz="0.00000000001"
        izz="0.00000000001" />
    </inertial>
    <visual>
      <origin
        xyz="0 0 0"
        rpy="0 0 0" />
      <geometry>
        <mesh
          filename="meshes/left_hand_thumb_rota_tip.STL" />
      </geometry>
      <material
        name="RAL_9005_Jet_Black">
        <color
          rgba="0.055 0.055 0.063 1" />
      </material>
    </visual>
    <collision>
      <origin
        xyz="0 0 0"
        rpy="0 0 0" />
      <geometry>
        <mesh
          filename="meshes/left_hand_thumb_rota_tip.STL" />
      </geometry>
    </collision>
  </link>
  <joint
    name="left_hand_thumb_rota_joint3"
    type="fixed">
    <origin
      xyz="0.0499881470979494 0 0"
      rpy="0 0 0" />
    <parent
      link="left_hand_thumb_rota_link2" />
    <child
      link="left_hand_thumb_rota_tip" />
    <axis
      xyz="0 0 0" />
    <dynamics
      damping="0"
      friction="0" />
  </joint>
  <link
    name="left_hand_index_bend_link">
    <inertial>
      <origin
        xyz="-0.000388464456994867 0.000992075604557427 -0.00970333167554097"
        rpy="0 0 0" />
      <mass
        value="0.06910833" />
      <inertia
        ixx="0.0000174"
        ixy="0.00000000001"
        ixz="0.00000000001"
        iyy="0.00001677"
        iyz="0.00000013"
        izz="0.00000345" />
    </inertial>
    <visual>
      <origin
        xyz="0 0 0"
        rpy="0 0 0" />
      <geometry>
        <mesh
          filename="meshes/left_hand_index_bend_link.STL" />
      </geometry>
      <material
        name="RAL_9005_Jet_Black">
        <color
          rgba="0.055 0.055 0.063 1" />
      </material>
    </visual>
    <!-- <collision>
      <origin
        xyz="0 0 0"
        rpy="0 0 0" />
      <geometry>
        <mesh
          filename="meshes/left_hand_index_bend_collide_link.STL" />
      </geometry>
    </collision> -->
  </link>
  <joint
    name="left_hand_index_bend_joint"
    type="revolute">
    <origin
      xyz="0.0265 -0.0065 -0.0899"
      rpy="0 0 0" />
    <parent
      link="left_hand_link" />
    <child
      link="left_hand_index_bend_link" />
    <axis
      xyz="0 -1 0" />
    <limit
      lower="-0.174"
      upper="0.174"
      effort="0.4"
      velocity="14.38" />
    <dynamics
      damping="0"
      friction="0" />
  </joint>
  <link
    name="left_hand_index_rota_link1">
    <inertial>
      <origin
        xyz="-3.58049083604185E-05 -0.00053041759210529 -0.0332784671157223"
        rpy="0 0 0" />
      <mass
        value="0.06298297" />
      <inertia
        ixx="0.00001738"
        ixy="0.00000000001"
        ixz="-0.00000028"
        iyy="0.00001686"
        iyz="-0.00000019"
        izz="0.0000032" />
    </inertial>
    <visual>
      <origin
        xyz="0 0 0"
        rpy="0 0 0" />
      <geometry>
        <mesh
          filename="meshes/left_hand_index_rota_link1.STL" />
      </geometry>
      <material
        name="RAL_9005_Jet_Black">
        <color
          rgba="0.055 0.055 0.063 1" />
      </material>
    </visual>
    <collision>
      <origin
        xyz="0 0 0"
        rpy="0 0 0" />
      <!-- <geometry>
        <mesh
          filename="meshes/left_hand_index_rota_x_link1.STL" />          
      </geometry> -->
      <geometry>
        <mesh
          filename="meshes/left_hand_index_rota_link1.STL" />          
      </geometry>

    </collision>
  </link>
  <joint
    name="left_hand_index_joint1"
    type="revolute">
    <origin
      xyz="0 0 -0.0178"
      rpy="0 0 0" />
    <parent
      link="left_hand_index_bend_link" />
    <child
      link="left_hand_index_rota_link1" />
    <axis
      xyz="-1 0 0" />
    <limit
      lower="0"
      upper="1.919"
      effort="1.1"
      velocity="8.63" />
    <dynamics
      damping="0"
      friction="0" />
  </joint>
  <link
    name="left_hand_index_rotaback_link1">
    <inertial>
      <origin
        xyz="0.00014803463945353 0.0115948039961551 0.0241234085631844"
        rpy="0 0 0" />
      <mass
        value="0.00000002" />
      <inertia
        ixx="0.00000000001"
        ixy="0.00000000001"
        ixz="0.00000000001"
        iyy="0.00000000001"
        iyz="0.00000000001"
        izz="0.00000000001" />
    </inertial>
    <visual>
      <origin
        xyz="0 0 0"
        rpy="0 0 0" />
      <geometry>
        <mesh
          filename="meshes/left_hand_index_rotaback_link1.STL" />
      </geometry>
      <material
        name="RAL_9003_Signal_White">
        <color
          rgba="0.941 0.941 0.941 1" />
      </material>
    </visual>
    <collision>
      <origin
        xyz="0 0 0"
        rpy="0 0 0" />
      <geometry>
        <mesh
          filename="meshes/left_hand_index_rotaback_link1.STL" />
      </geometry>
    </collision>
  </link>
  <joint
    name="left_hand_index_rotaback_joint1"
    type="fixed">
    <origin
      xyz="0 0 -0.0558000000000001"
      rpy="0 0 0" />
    <parent
      link="left_hand_index_rota_link1" />
    <child
      link="left_hand_index_rotaback_link1" />
    <axis
      xyz="0 0 0" />
    <dynamics
      damping="0"
      friction="0" />
  </joint>
  <link
    name="left_hand_index_rota_link2">
    <inertial>
      <origin
        xyz="0.000248361662016118 -0.00119905190206697 -0.0213789854478661"
        rpy="0 0 0" />
      <mass
        value="0.01588724" />
      <inertia
        ixx="0.00000277"
        ixy="0.00000000001"
        ixz="-0.00000012"
        iyy="0.00000283"
        iyz="-0.00000007"
        izz="0.00000085" />
    </inertial>
    <visual>
      <origin
        xyz="0 0 0"
        rpy="0 0 0" />
      <geometry>
        <mesh
          filename="meshes/left_hand_index_rota_link2.STL" />
      </geometry>
      <material
        name="RAL_9005_Jet_Black">
        <color
          rgba="0.055 0.055 0.063 1" />
      </material>
    </visual>
    <collision>
      <origin
        xyz="0 0 0"
        rpy="0 0 0" />
      <geometry>
        <mesh
          filename="meshes/left_hand_index_rota_link2.STL" />
      </geometry>
    </collision>
  </link>
  <joint
    name="left_hand_index_joint2"
    type="revolute">
    <origin
      xyz="0 0 -0.0558"
      rpy="0 0 0" />
    <parent
      link="left_hand_index_rota_link1" />
    <child
      link="left_hand_index_rota_link2" />
    <axis
      xyz="-1 0 0" />
    <limit
      lower="0"
      upper="1.919"
      effort="0.4"
      velocity="14.38" />
    <dynamics
      damping="0"
      friction="0" />
  </joint>
  <link
    name="left_hand_index_rotaback_link2">
    <inertial>
      <origin
        xyz="-0.000157950438605944 0.00758843721876324 0.017665521085575"
        rpy="0 0 0" />
      <mass
        value="0.00000001" />
      <inertia
        ixx="0.00000000001"
        ixy="0.00000000001"
        ixz="0.00000000001"
        iyy="0.00000000001"
        iyz="0.00000000001"
        izz="0.00000000001" />
    </inertial>
    <visual>
      <origin
        xyz="0 0 0"
        rpy="0 0 0" />
      <geometry>
        <mesh
          filename="meshes/left_hand_index_rotaback_link2.STL" />
      </geometry>
      <material
        name="RAL_9003_Signal_White">
        <color
          rgba="0.941 0.941 0.941 1" />
      </material>
    </visual>
    <collision>
      <origin
        xyz="0 0 0"
        rpy="0 0 0" />
      <geometry>
        <mesh
          filename="meshes/left_hand_index_rotaback_link2.STL" />
      </geometry>
    </collision>
  </link>
  <joint
    name="left_hand_index_rotaback_joint2"
    type="fixed">
    <origin
      xyz="0 0 -0.0422482924089404"
      rpy="0 0 0" />
    <parent
      link="left_hand_index_rota_link2" />
    <child
      link="left_hand_index_rotaback_link2" />
    <axis
      xyz="0 0 0" />
    <dynamics
      damping="0"
      friction="0" />
  </joint>
  <link
    name="left_hand_index_rota_tip">
    <inertial>
      <origin
        xyz="-1.00613961606655E-16 1.90819582357449E-17 0"
        rpy="0 0 0" />
      <mass
        value="0.00000565" />
      <inertia
        ixx="0.00000000001"
        ixy="0.00000000001"
        ixz="0.00000000001"
        iyy="0.00000000001"
        iyz="0.00000000001"
        izz="0.00000000001" />
    </inertial>
    <visual>
      <origin
        xyz="0 0 0"
        rpy="0 0 0" />
      <geometry>
        <mesh
          filename="meshes/left_hand_index_rota_tip.STL" />
      </geometry>
      <material
        name="RAL_9005_Jet_Black">
        <color
          rgba="0.055 0.055 0.063 1" />
      </material>
    </visual>
    <collision>
      <origin
        xyz="0 0 0"
        rpy="0 0 0" />
      <geometry>
        <mesh
          filename="meshes/left_hand_index_rota_tip.STL" />
      </geometry>
    </collision>
  </link>
  <joint
    name="left_hand_index_rota_joint3"
    type="fixed">
    <origin
      xyz="0 0 -0.0422482924089404"
      rpy="0 0 0" />
    <parent
      link="left_hand_index_rota_link2" />
    <child
      link="left_hand_index_rota_tip" />
    <axis
      xyz="0 0 0" />
    <dynamics
      damping="0"
      friction="0" />
  </joint>
  <link
    name="left_hand_mid_link1">
    <inertial>
      <origin
        xyz="-3.58049083603916E-05 -0.000530417592105155 -0.0332784671157224"
        rpy="0 0 0" />
      <mass
        value="0.06298297" />
      <inertia
        ixx="0.00001738"
        ixy="0.00000000001"
        ixz="-0.00000028"
        iyy="0.00001686"
        iyz="-0.00000019"
        izz="0.0000032" />
    </inertial>
    <visual>
      <origin
        xyz="0 0 0"
        rpy="0 0 0" />
      <geometry>
        <mesh
          filename="meshes/left_hand_mid_link1.STL" />
      </geometry>
      <material
        name="RAL_9005_Jet_Black">
        <color
          rgba="0.055 0.055 0.063 1" />
      </material>
    </visual>
    <collision>
      <origin
        xyz="0 0 0"
        rpy="0 0 0" />
      <geometry>
        <mesh
          filename="meshes/left_hand_mid_link1.STL" />
      </geometry>
    </collision>
  </link>
  <joint
    name="left_hand_mid_joint1"
    type="revolute">
    <origin
      xyz="0.004 -0.0065 -0.1082"
      rpy="0 0 0" />
    <parent
      link="left_hand_link" />
    <child
      link="left_hand_mid_link1" />
    <axis
      xyz="-1 0 0" />
    <limit
      lower="0"
      upper="1.919"
      effort="1.1"
      velocity="8.63" />
    <dynamics
      damping="0"
      friction="0" />
  </joint>
  <link
    name="left_hand_midback_link1">
    <inertial>
      <origin
        xyz="0.000148034858018445 0.0115948038778314 0.024123407735519"
        rpy="0 0 0" />
      <mass
        value="0.00000002" />
      <inertia
        ixx="0.00000000001"
        ixy="0.00000000001"
        ixz="0.00000000001"
        iyy="0.00000000001"
        iyz="0.00000000001"
        izz="0.00000000001" />
    </inertial>
    <visual>
      <origin
        xyz="0 0 0"
        rpy="0 0 0" />
      <geometry>
        <mesh
          filename="meshes/left_hand_midback_link1.STL" />
      </geometry>
      <material
        name="RAL_9003_Signal_White">
        <color
          rgba="0.941 0.941 0.941 1" />
      </material>
    </visual>
    <collision>
      <origin
        xyz="0 0 0"
        rpy="0 0 0" />
      <geometry>
        <mesh
          filename="meshes/left_hand_midback_link1.STL" />
      </geometry>
    </collision>
  </link>
  <joint
    name="left_hand_midback_joint1"
    type="fixed">
    <origin
      xyz="0 0 -0.0558000000000001"
      rpy="0 0 0" />
    <parent
      link="left_hand_mid_link1" />
    <child
      link="left_hand_midback_link1" />
    <axis
      xyz="0 0 0" />
    <dynamics
      damping="0"
      friction="0" />
  </joint>
  <link
    name="left_hand_mid_link2">
    <inertial>
      <origin
        xyz="0.000248361662016048 -0.00119905190206678 -0.0213789854478656"
        rpy="0 0 0" />
      <mass
        value="0.01588724" />
      <inertia
        ixx="0.00000277"
        ixy="0.00000000001"
        ixz="-0.00000012"
        iyy="0.00000283"
        iyz="-0.00000007"
        izz="0.00000085" />
    </inertial>
    <visual>
      <origin
        xyz="0 0 0"
        rpy="0 0 0" />
      <geometry>
        <mesh
          filename="meshes/left_hand_mid_link2.STL" />
      </geometry>
      <material
        name="RAL_9005_Jet_Black">
        <color
          rgba="0.055 0.055 0.063 1" />
      </material>
    </visual>
    <collision>
      <origin
        xyz="0 0 0"
        rpy="0 0 0" />
      <geometry>
        <mesh
          filename="meshes/left_hand_mid_link2.STL" />
      </geometry>
    </collision>
  </link>
  <joint
    name="left_hand_mid_joint2"
    type="revolute">
    <origin
      xyz="0 0 -0.0558"
      rpy="0 0 0" />
    <parent
      link="left_hand_mid_link1" />
    <child
      link="left_hand_mid_link2" />
    <axis
      xyz="-1 0 0" />
    <limit
      lower="0"
      upper="1.919"
      effort="0.4"
      velocity="14.38" />
    <dynamics
      damping="0"
      friction="0" />
  </joint>
  <link
    name="left_hand_midback_link2">
    <inertial>
      <origin
        xyz="-0.000157950438634382 0.00758843721877263 0.0176655210856587"
        rpy="0 0 0" />
      <mass
        value="0.00000001" />
      <inertia
        ixx="0.00000000001"
        ixy="0.00000000001"
        ixz="0.00000000001"
        iyy="0.00000000001"
        iyz="0.00000000001"
        izz="0.00000000001" />
    </inertial>
    <visual>
      <origin
        xyz="0 0 0"
        rpy="0 0 0" />
      <geometry>
        <mesh
          filename="meshes/left_hand_midback_link2.STL" />
      </geometry>
      <material
        name="RAL_9003_Signal_White">
        <color
          rgba="0.941 0.941 0.941 1" />
      </material>
    </visual>
    <collision>
      <origin
        xyz="0 0 0"
        rpy="0 0 0" />
      <geometry>
        <mesh
          filename="meshes/left_hand_midback_link2.STL" />
      </geometry>
    </collision>
  </link>
  <joint
    name="left_hand_midback_joint2"
    type="fixed">
    <origin
      xyz="0 0 -0.0422482924089403"
      rpy="0 0 0" />
    <parent
      link="left_hand_mid_link2" />
    <child
      link="left_hand_midback_link2" />
    <axis
      xyz="0 0 0" />
    <dynamics
      damping="0"
      friction="0" />
  </joint>
  <link
    name="left_hand_mid_tip">
    <inertial>
      <origin
        xyz="-1.90819582357449E-17 1.55257751099924E-16 0"
        rpy="0 0 0" />
      <mass
        value="0.00000565" />
      <inertia
        ixx="0.00000000001"
        ixy="0.00000000001"
        ixz="0.00000000001"
        iyy="0.00000000001"
        iyz="0.00000000001"
        izz="0.00000000001" />
    </inertial>
    <visual>
      <origin
        xyz="0 0 0"
        rpy="0 0 0" />
      <geometry>
        <mesh
          filename="meshes/left_hand_mid_tip.STL" />
      </geometry>
      <material
        name="RAL_9005_Jet_Black">
        <color
          rgba="0.055 0.055 0.063 1" />
      </material>
    </visual>
    <collision>
      <origin
        xyz="0 0 0"
        rpy="0 0 0" />
      <geometry>
        <mesh
          filename="meshes/left_hand_mid_tip.STL" />
      </geometry>
    </collision>
  </link>
  <joint
    name="left_hand_mid_joint3"
    type="fixed">
    <origin
      xyz="0 0 -0.0422482924089403"
      rpy="0 0 0" />
    <parent
      link="left_hand_mid_link2" />
    <child
      link="left_hand_mid_tip" />
    <axis
      xyz="0 0 0" />
    <dynamics
      damping="0"
      friction="0" />
  </joint>
  <link
    name="left_hand_ring_link1">
    <inertial>
      <origin
        xyz="-3.58049083603491E-05 -0.000530417592105894 -0.0332784671157224"
        rpy="0 0 0" />
      <mass
        value="0.06298297" />
      <inertia
        ixx="0.00001738"
        ixy="0.00000000001"
        ixz="-0.00000028"
        iyy="0.00001686"
        iyz="-0.00000019"
        izz="0.0000032" />
    </inertial>
    <visual>
      <origin
        xyz="0 0 0"
        rpy="0 0 0" />
      <geometry>
        <mesh
          filename="meshes/left_hand_ring_link1.STL" />
      </geometry>
      <material
        name="RAL_9005_Jet_Black">
        <color
          rgba="0.055 0.055 0.063 1" />
      </material>
    </visual>
    <collision>
      <origin
        xyz="0 0 0"
        rpy="0 0 0" />
      <geometry>
        <mesh
          filename="meshes/left_hand_ring_link1.STL" />
      </geometry>
    </collision>
  </link>
  <joint
    name="left_hand_ring_joint1"
    type="revolute">
    <origin
      xyz="-0.016 -0.0065 -0.1052"
      rpy="0 0 0" />
    <parent
      link="left_hand_link" />
    <child
      link="left_hand_ring_link1" />
    <axis
      xyz="-1 0 0" />
    <limit
      lower="0"
      upper="1.919"
      effort="1.1"
      velocity="8.63" />
    <dynamics
      damping="0"
      friction="0" />
  </joint>
  <link
    name="left_hand_ringback_link1">
    <inertial>
      <origin
        xyz="0.000148033930314071 0.0115948038916307 0.0241234089720673"
        rpy="0 0 0" />
      <mass
        value="0.00000002" />
      <inertia
        ixx="0.00000000001"
        ixy="0.00000000001"
        ixz="0.00000000001"
        iyy="0.00000000001"
        iyz="0.00000000001"
        izz="0.00000000001" />
    </inertial>
    <visual>
      <origin
        xyz="0 0 0"
        rpy="0 0 0" />
      <geometry>
        <mesh
          filename="meshes/left_hand_ringback_link1.STL" />
      </geometry>
      <material
        name="RAL_9003_Signal_White">
        <color
          rgba="0.941 0.941 0.941 1" />
      </material>
    </visual>
    <collision>
      <origin
        xyz="0 0 0"
        rpy="0 0 0" />
      <geometry>
        <mesh
          filename="meshes/left_hand_ringback_link1.STL" />
      </geometry>
    </collision>
  </link>
  <joint
    name="left_hand_ringback_joint1"
    type="fixed">
    <origin
      xyz="0 0 -0.0558000000000001"
      rpy="0 0 0" />
    <parent
      link="left_hand_ring_link1" />
    <child
      link="left_hand_ringback_link1" />
    <axis
      xyz="0 0 0" />
    <dynamics
      damping="0"
      friction="0" />
  </joint>
  <link
    name="left_hand_ring_link2">
    <inertial>
      <origin
        xyz="0.000248361662016028 -0.0011990519020675 -0.0213789854478657"
        rpy="0 0 0" />
      <mass
        value="0.01588724" />
      <inertia
        ixx="0.00000277"
        ixy="0.00000000001"
        ixz="-0.00000012"
        iyy="0.00000283"
        iyz="-0.00000007"
        izz="0.00000085" />
    </inertial>
    <visual>
      <origin
        xyz="0 0 0"
        rpy="0 0 0" />
      <geometry>
        <mesh
          filename="meshes/left_hand_ring_link2.STL" />
      </geometry>
      <material
        name="RAL_9005_Jet_Black">
        <color
          rgba="0.055 0.055 0.063 1" />
      </material>
    </visual>
    <collision>
      <origin
        xyz="0 0 0"
        rpy="0 0 0" />
      <geometry>
        <mesh
          filename="meshes/left_hand_ring_link2.STL" />
      </geometry>
    </collision>
  </link>
  <joint
    name="left_hand_ring_joint2"
    type="revolute">
    <origin
      xyz="0 0 -0.0558"
      rpy="0 0 0" />
    <parent
      link="left_hand_ring_link1" />
    <child
      link="left_hand_ring_link2" />
    <axis
      xyz="-1 0 0" />
    <limit
      lower="0"
      upper="1.919"
      effort="0.4"
      velocity="14.38" />
    <dynamics
      damping="0"
      friction="0" />
  </joint>
  <link
    name="left_hand_ringback_link2">
    <inertial>
      <origin
        xyz="-0.000157950438606443 0.00758843721877125 0.0176655210856417"
        rpy="0 0 0" />
      <mass
        value="0.00000001" />
      <inertia
        ixx="0.00000000001"
        ixy="0.00000000001"
        ixz="0.00000000001"
        iyy="0.00000000001"
        iyz="0.00000000001"
        izz="0.00000000001" />
    </inertial>
    <visual>
      <origin
        xyz="0 0 0"
        rpy="0 0 0" />
      <geometry>
        <mesh
          filename="meshes/left_hand_ringback_link2.STL" />
      </geometry>
      <material
        name="RAL_9003_Signal_White">
        <color
          rgba="0.941 0.941 0.941 1" />
      </material>
    </visual>
    <collision>
      <origin
        xyz="0 0 0"
        rpy="0 0 0" />
      <geometry>
        <mesh
          filename="meshes/left_hand_ringback_link2.STL" />
      </geometry>
    </collision>
  </link>
  <joint
    name="left_hand_ringback_joint2"
    type="fixed">
    <origin
      xyz="0 0 -0.0422482924089404"
      rpy="0 0 0" />
    <parent
      link="left_hand_ring_link2" />
    <child
      link="left_hand_ringback_link2" />
    <axis
      xyz="0 0 0" />
    <dynamics
      damping="0"
      friction="0" />
  </joint>
  <link
    name="left_hand_ring_tip">
    <inertial>
      <origin
        xyz="-4.85722573273506E-17 -5.31692745386891E-16 0"
        rpy="0 0 0" />
      <mass
        value="0.00000565" />
      <inertia
        ixx="0.00000000001"
        ixy="0.00000000001"
        ixz="0.00000000001"
        iyy="0.00000000001"
        iyz="0.00000000001"
        izz="0.00000000001" />
    </inertial>
    <visual>
      <origin
        xyz="0 0 0"
        rpy="0 0 0" />
      <geometry>
        <mesh
          filename="meshes/left_hand_ring_tip.STL" />
      </geometry>
      <material
        name="RAL_9005_Jet_Black">
        <color
          rgba="0.055 0.055 0.063 1" />
      </material>
    </visual>
    <collision>
      <origin
        xyz="0 0 0"
        rpy="0 0 0" />
      <geometry>
        <mesh
          filename="meshes/left_hand_ring_tip.STL" />
      </geometry>
    </collision>
  </link>
  <joint
    name="left_hand_ring_joint3"
    type="fixed">
    <origin
      xyz="0 0 -0.0422482924089404"
      rpy="0 0 0" />
    <parent
      link="left_hand_ring_link2" />
    <child
      link="left_hand_ring_tip" />
    <axis
      xyz="0 0 0" />
    <dynamics
      damping="0"
      friction="0" />
  </joint>
  <link
    name="left_hand_pinky_link1">
    <inertial>
      <origin
        xyz="-3.58049083603318E-05 -0.000530417592106195 -0.0332784671157224"
        rpy="0 0 0" />
      <mass
        value="0.06298297" />
      <inertia
        ixx="0.00001738"
        ixy="0.00000000001"
        ixz="-0.00000028"
        iyy="0.00001686"
        iyz="-0.00000019"
        izz="0.0000032" />
    </inertial>
    <visual>
      <origin
        xyz="0 0 0"
        rpy="0 0 0" />
      <geometry>
        <mesh
          filename="meshes/left_hand_pinky_link1.STL" />
      </geometry>
      <material
        name="RAL_9005_Jet_Black">
        <color
          rgba="0.055 0.055 0.063 1" />
      </material>
    </visual>
    <collision>
      <origin
        xyz="0 0 0"
        rpy="0 0 0" />
      <geometry>
        <mesh
          filename="meshes/left_hand_pinky_link1.STL" />
      </geometry>
    </collision>
  </link>
  <joint
    name="left_hand_pinky_joint1"
    type="revolute">
    <origin
      xyz="-0.036 -0.0065 -0.1022"
      rpy="0 0 0" />
    <parent
      link="left_hand_link" />
    <child
      link="left_hand_pinky_link1" />
    <axis
      xyz="-1 0 0" />
    <limit
      lower="0"
      upper="1.919"
      effort="1.1"
      velocity="8.63" />
    <dynamics
      damping="0"
      friction="0" />
  </joint>
  <link
    name="left_hand_pinkyback_link1">
    <inertial>
      <origin
        xyz="0.000148034877008783 0.0115948040346325 0.024123408080182"
        rpy="0 0 0" />
      <mass
        value="0.00000002" />
      <inertia
         ixx="0.00000000001"
        ixy="0.00000000001"
        ixz="0.00000000001"
        iyy="0.00000000001"
        iyz="0.00000000001"
        izz="0.00000000001"/>
    </inertial>
    <visual>
      <origin
        xyz="0 0 0"
        rpy="0 0 0" />
      <geometry>
        <mesh
          filename="meshes/left_hand_pinkyback_link1.STL" />
      </geometry>
      <material
        name="RAL_9003_Signal_White">
        <color
          rgba="0.941 0.941 0.941 1" />
      </material>
    </visual>
    <collision>
      <origin
        xyz="0 0 0"
        rpy="0 0 0" />
      <geometry>
        <mesh
          filename="meshes/left_hand_pinkyback_link1.STL" />
      </geometry>
    </collision>
  </link>
  <joint
    name="left_hand_pinkyback_joint1"
    type="fixed">
    <origin
      xyz="0 0 -0.0558000000000001"
      rpy="0 0 0" />
    <parent
      link="left_hand_pinky_link1" />
    <child
      link="left_hand_pinkyback_link1" />
    <axis
      xyz="0 0 0" />
    <dynamics
      damping="0"
      friction="0" />
  </joint>
  <link
    name="left_hand_pinky_link2">
    <inertial>
      <origin
        xyz="0.000248361696242753 -0.00119905185762272 -0.0213789857007834"
        rpy="0 0 0" />
      <mass
        value="0.01588724" />
      <inertia
        ixx="0.00000277"
        ixy="0.00000000001"
        ixz="-0.00000012"
        iyy="0.00000283"
        iyz="-0.00000007"
        izz="0.00000085" />
    </inertial>
    <visual>
      <origin
        xyz="0 0 0"
        rpy="0 0 0" />
      <geometry>
        <mesh
          filename="meshes/left_hand_pinky_link2.STL" />
      </geometry>
      <material
        name="RAL_9005_Jet_Black">
        <color
          rgba="0.055 0.055 0.063 1" />
      </material>
    </visual>
    <collision>
      <origin
        xyz="0 0 0"
        rpy="0 0 0" />
      <geometry>
        <mesh
          filename="meshes/left_hand_pinky_link2.STL" />
      </geometry>
    </collision>
  </link>
  <joint
    name="left_hand_pinky_joint2"
    type="revolute">
    <origin
      xyz="0 0 -0.0558"
      rpy="0 0 0" />
    <parent
      link="left_hand_pinky_link1" />
    <child
      link="left_hand_pinky_link2" />
    <axis
      xyz="-1 0 0" />
    <limit
      lower="0"
      upper="1.919"
      effort="0.4"
      velocity="14.38" />
    <dynamics
      damping="0"
      friction="0" />
  </joint>
  <link
    name="left_hand_pinkyback_link2">
    <inertial>
      <origin
        xyz="-0.0001579504385983 0.00758843721876557 0.0176655210856048"
        rpy="0 0 0" />
      <mass
        value="0.00000001" />
      <inertia
         ixx="0.00000000001"
        ixy="0.00000000001"
        ixz="0.00000000001"
        iyy="0.00000000001"
        iyz="0.00000000001"
        izz="0.00000000001"/>
    </inertial>
    <visual>
      <origin
        xyz="0 0 0"
        rpy="0 0 0" />
      <geometry>
        <mesh
          filename="meshes/left_hand_pinkyback_link2.STL" />
      </geometry>
      <material
        name="RAL_9003_Signal_White">
        <color
          rgba="0.941 0.941 0.941 1" />
      </material>
    </visual>
    <collision>
      <origin
        xyz="0 0 0"
        rpy="0 0 0" />
      <geometry>
        <mesh
          filename="meshes/left_hand_pinkyback_link2.STL" />
      </geometry>
    </collision>
  </link>
  <joint
    name="left_hand_pinkyback_joint2"
    type="fixed">
    <origin
      xyz="0 0 -0.0422482924089405"
      rpy="0 0 0" />
    <parent
      link="left_hand_pinky_link2" />
    <child
      link="left_hand_pinkyback_link2" />
    <axis
      xyz="0 0 0" />
    <dynamics
      damping="0"
      friction="0" />
  </joint>
  <link
    name="left_hand_pinky_tip">
    <inertial>
      <origin
        xyz="1.38777878078145E-17 -8.84708972748172E-16 2.77555756156289E-17"
        rpy="0 0 0" />
      <mass
        value="0.00000565" />
      <inertia
         ixx="0.00000000001"
        ixy="0.00000000001"
        ixz="0.00000000001"
        iyy="0.00000000001"
        iyz="0.00000000001"
        izz="0.00000000001"/>
    </inertial>
    <visual>
      <origin
        xyz="0 0 0"
        rpy="0 0 0" />
      <geometry>
        <mesh
          filename="meshes/left_hand_pinky_tip.STL" />
      </geometry>
      <material
        name="RAL_9005_Jet_Black">
        <color
          rgba="0.055 0.055 0.063 1" />
      </material>
    </visual>
    <collision>
      <origin
        xyz="0 0 0"
        rpy="0 0 0" />
      <geometry>
        <mesh
          filename="meshes/left_hand_pinky_tip.STL" />
      </geometry>
    </collision>
  </link>
  <joint
    name="left_hand_pinky_joint3"
    type="fixed">
    <origin
      xyz="0 0 -0.0422482924089405"
      rpy="0 0 0" />
    <parent
      link="left_hand_pinky_link2" />
    <child
      link="left_hand_pinky_tip" />
    <axis
      xyz="0 0 0" />
    <dynamics
      damping="0"
      friction="0" />
  </joint>
</robot>